Workbook

Sheet Инструкция
A1: Фаза 1: выбор концепции проекта (нечёткий коллективный TOPSIS и чёткий коллективный МАИ)
A3: Команда из двух экспертов: Савелий Хвостов, Екатерина Козлова. Концепций 4, критериев 5.
A5: Что заполнять (жёлтые ячейки, синий шрифт). Каждый эксперт заполняет только свои блоки и не смотрит чужие до конца.
A6: 1. «Оценки»: оценка каждой концепции по каждому критерию тройкой (l ≤ m ≤ u) по шкале 1–10:
A7: l = наименьшее возможное, m = наиболее ожидаемое, u = наибольшее возможное. Шкала всегда «сколько этого свойства»:
A8: для max-критериев l пессимистичная, u оптимистичная; для min-критериев (трудоёмкость, риски) наоборот: u пессимистичная.
A9: для трудоёмкости 10 = очень трудоёмко, для рисков 10 = очень рискованно (метод сам учтёт, что это min-критерии).
A10: Строка w: важность критерия тройкой на шкале 0–1 (l ≤ m ≤ u).
A11: 2. «МАИ Эксперт 1» и «МАИ Эксперт 2»: верхний треугольник 6 матриц парных сравнений по шкале Саати:
A12: 1 одинаково, 3 немного лучше, 5 лучше, 7 значительно лучше, 9 абсолютно лучше, 2/4/6/8 промежуточные;
A13: если строка хуже столбца, ставится дробь (=1/3, =1/5, …). В матрицах концепций «лучше» значит «лучше по этому критерию»:
A14: для трудоёмкости и рисков лучше та концепция, у которой их МЕНЬШЕ.
... A31: • Глобальный приоритет концепции = Σ(вес критерия × локальный приоритет концепции).

Sheet Концепции
A1: Концепции и критерии
A3: Код | B3: Концепция | C3: Описание
A4: A1 | B4: Доска домашек группы | C4: Telegram-бот группы: студенты добавляют задания и сроки по предметам, бот напоминает о дедлайнах, каждый отмечает выполненное, по команде выводится сводка на неделю
A5: A2 | B5: Очередь на защиту лабораторных | C5: Веб-сервис: преподаватель открывает слоты сдачи, студенты записываются в очередь, получают уведомление, когда подходит их очередь, преподаватель отмечает результат защиты
A6: A3 | B6: Общие расходы с друзьями | C6: Telegram-бот для компании друзей: в поездке или на встрече каждый вносит, кто за что заплатил, бот считает, кто кому сколько должен, сводит долги к минимуму переводов, напоминает о долге, получатель отмечает возврат
A7: A4 | B7: Трекер подписок | C7: Веб-приложение: список регулярных списаний с суммой и датой, напоминание за день до оплаты, итог расходов на подписки в месяц, подсказка отменить подписку, которой давно не пользовались
A10: Код | B10: Критерий | C10: Тип (max/min) | D10: Что оценивает
A11: C1 | B11: Полезность для пользователей | C11: max | D11: Насколько продукт решает реальную и частую проблему целевой аудитории
A12: C2 | B12: Трудоёмкость реализации | C12: min | D12: Объём и сложность работ при условии 10–15 use case
A13: C3 | B13: Внешние зависимости и риски | C13: min | D13: Зависимость от сторонних API, платформ и данных, юридические и эксплуатационные риски
A14: C4 | B14: Понятность предметной области | C14: max | D14: Насколько команде знакома область: легко ли писать use case и оценивать работы в фазах 2–5
A15: C5 | B15: Интерес команды | C15: max | D15: Насколько команде интересно вести этот проект весь семестр и разбираться в его предметной области

Sheet Оценки
A1: Экспертные оценки: нечёткие трёхточечные числа (l ≤ m ≤ u), концепции по шкале 1–10, веса по шкале 0–1
A3: Эксперт 1 (Савелий Хвостов)
B4: Концепция | C4: =Концепции!$B$11 | F4: =Концепции!$B$12 | I4: =Концепции!$B$13 | L4: =Концепции!$B$14 | O4: =Концепции!$B$15
C5: l | D5: m | E5: u | F5: l | G5: m | H5: u | I5: l | J5: m | K5: u | L5: l | M5: m | N5: u | O5: l | P5: m | Q5: u
A6: A1 | B6: =Концепции!$B$4 | C6: 5 | D6: 7 | E6: 9 | F6: 2 | G6: 3 | H6: 5 | I6: 8 | J6: 8 | K6: 8 | L6: 6 | M6: 8 | N6: 10 | O6: 7 | P6: 8 | Q6: 10
A7: A2 | B7: =Концепции!$B$5 | C7: 3 | D7: 6 | E7: 8 | F7: 5 | G7: 7 | H7: 8 | I7: 8 | J7: 10 | K7: 10 | L7: 5 | M7: 7 | N7: 10 | O7: 2 | P7: 6 | Q7: 7
A8: A3 | B8: =Концепции!$B$6 | C8: 2 | D8: 5 | E8: 7 | F8: 2 | G8: 5 | H8: 6 | I8: 3 | J8: 5 | K8: 7 | L8: 6 | M8: 9 | N8: 10 | O8: 8 | P8: 8 | Q8: 9
A9: A4 | B9: =Концепции!$B$7 | C9: 6 | D9: 8 | E9: 10 | F9: 1 | G9: 3 | H9: 4 | I9: 3 | J9: 3 | K9: 3 | L9: 8 | M9: 10 | N9: 10 | O9: 8 | P9: 8 | Q9: 10
A10: w | B10: Важность критерия (0–1) | C10: 0.7 | D10: 0.8 | E10: 0.9 | F10: 0.5 | G10: 0.6 | H10: 0.7 | I10: 0.3 | J10: 0.6 | K10: 0.8 | L10: 0.2 | M10: 0.5 | N10: 0.8 | O10: 0.5 | P10: 0.75 | Q10: 1
B11: Проверка l ≤ m ≤ u | C11: =IF(COUNT(C6:E10)<15,"не заполнено",IF(SUMPRODUCT((C6:C10>D6:D10)+(D6:D10>E6:E10))=0,"ok","порядок!")) | F11: =IF(COUNT(F6:H10)<15,"не заполнено",IF(SUMPRODUCT((F6:F10>G6:G10)+(G6:G10>H6:H10))=0,"ok","порядок!")) | I11: =IF(COUNT(I6:K10)<15,"не заполнено",IF(SUMPRODUCT((I6:I10>J6:J10)+(J6:J10>K6:K10))=0,"ok","порядок!")) | L11: =IF(COUNT(L6:N10)<15,"не заполнено",IF(SUMPRODUCT((L6:L10>M6:M10)+(M6:M10>N6:N10))=0,"ok","порядок!")) | O11: =IF(COUNT(O6:Q10)<15,"не заполнено",IF(SUMPRODUCT((O6:O10>P6:P10)+(P6:P10>Q6:Q10))=0,"ok","порядок!"))
A13: Эксперт 2 (Екатерина Козлова)
B14: Концепция | C14: =Концепции!$B$11 | F14: =Концепции!$B$12 | I14: =Концепции!$B$13 | L14: =Концепции!$B$14 | O14: =Концепции!$B$15
C15: l | D15: m | E15: u | F15: l | G15: m | H15: u | I15: l | J15: m | K15: u | L15: l | M15: m | N15: u | O15: l | P15: m | Q15: u
A16: A1 | B16: =Концепции!$B$4 | C16: 5 | D16: 7 | E16: 8 | F16: 3 | G16: 5 | H16: 7 | I16: 2 | J16: 4 | K16: 6 | L16: 3 | M16: 6 | N16: 8 | O16: 5 | P16: 7 | Q16: 8
A17: A2 | B17: =Концепции!$B$5 | C17: 3 | D17: 5 | E17: 6 | F17: 2 | G17: 4 | H17: 6 | I17: 1 | J17: 3 | K17: 5 | L17: 2 | M17: 5 | N17: 7 | O17: 3 | P17: 5 | Q17: 7
A18: A3 | B18: =Концепции!$B$6 | C18: 1 | D18: 3 | E18: 4 | F18: 5 | G18: 7 | H18: 9 | I18: 4 | J18: 6 | K18: 8 | L18: 4 | M18: 7 | N18: 9 | O18: 2 | P18: 4 | Q18: 6
A19: A4 | B19: =Концепции!$B$7 | C19: 7 | D19: 9 | E19: 10 | F19: 4 | G19: 6 | H19: 8 | I19: 3 | J19: 5 | K19: 7 | L19: 5 | M19: 8 | N19: 10 | O19: 7 | P19: 9 | Q19: 10
A20: w | B20: Важность критерия (0–1) | C20: 0.7 | D20: 0.85 | E20: 1 | F20: 0.4 | G20: 0.6 | H20: 0.8 | I20: 0.5 | J20: 0.7 | K20: 0.9 | L20: 0.4 | M20: 0.6 | N20: 0.8 | O20: 0.6 | P20: 0.8 | Q20: 1
B21: Проверка l ≤ m ≤ u | C21: =IF(COUNT(C16:E20)<15,"не заполнено",IF(SUMPRODUCT((C16:C20>D16:D20)+(D16:D20>E16:E20))=0,"ok","порядок!")) | F21: =IF(COUNT(F16:H20)<15,"не заполнено",IF(SUMPRODUCT((F16:F20>G16:G20)+(G16:G20>H16:H20))=0,"ok","порядок!")) | I21: =IF(COUNT(I16:K20)<15,"не заполнено",IF(SUMPRODUCT((I16:I20>J16:J20)+(J16:J20>K16:K20))=0,"ok","порядок!")) | L21: =IF(COUNT(L16:N20)<15,"не заполнено",IF(SUMPRODUCT((L16:L20>M16:M20)+(M16:M20>N16:N20))=0,"ok","порядок!")) | O21: =IF(COUNT(O16:Q20)<15,"не заполнено",IF(SUMPRODUCT((O16:O20>P16:P20)+(P16:P20>Q16:Q20))=0,"ok","порядок!"))

Sheet TOPSIS
A1: Нечёткий коллективный метод TOPSIS
A3: 1. Агрегированная матрица (l = MIN, m = СРЗНАЧ, u = MAX по экспертам)
B4: Концепция | C4: =Концепции!$B$11 | F4: =Концепции!$B$12 | I4: =Концепции!$B$13 | L4: =Концепции!$B$14 | O4: =Концепции!$B$15
C5: l | D5: m | E5: u | F5: l | G5: m | H5: u | I5: l | J5: m | K5: u | L5: l | M5: m | N5: u | O5: l | P5: m | Q5: u
A6: A1 | B6: =Концепции!$B$4 | C6: =MIN(Оценки!$C$6,Оценки!$C$16) | D6: =AVERAGE(Оценки!$D$6,Оценки!$D$16) | E6: =MAX(Оценки!$E$6,Оценки!$E$16) | F6: =MIN(Оценки!$F$6,Оценки!$F$16) | G6: =AVERAGE(Оценки!$G$6,Оценки!$G$16) | H6: =MAX(Оценки!$H$6,Оценки!$H$16) | I6: =MIN(Оценки!$I$6,Оценки!$I$16) | J6: =AVERAGE(Оценки!$J$6,Оценки!$J$16) | K6: =MAX(Оценки!$K$6,Оценки!$K$16) | L6: =MIN(Оценки!$L$6,Оценки!$L$16) | M6: =AVERAGE(Оценки!$M$6,Оценки!$M$16) | N6: =MAX(Оценки!$N$6,Оценки!$N$16) | O6: =MIN(Оценки!$O$6,Оценки!$O$16) | P6: =AVERAGE(Оценки!$P$6,Оценки!$P$16) | Q6: =MAX(Оценки!$Q$6,Оценки!$Q$16)
A7: A2 | B7: =Концепции!$B$5 | C7: =MIN(Оценки!$C$7,Оценки!$C$17) | D7: =AVERAGE(Оценки!$D$7,Оценки!$D$17) | E7: =MAX(Оценки!$E$7,Оценки!$E$17) | F7: =MIN(Оценки!$F$7,Оценки!$F$17) | G7: =AVERAGE(Оценки!$G$7,Оценки!$G$17) | H7: =MAX(Оценки!$H$7,Оценки!$H$17) | I7: =MIN(Оценки!$I$7,Оценки!$I$17) | J7: =AVERAGE(Оценки!$J$7,Оценки!$J$17) | K7: =MAX(Оценки!$K$7,Оценки!$K$17) | L7: =MIN(Оценки!$L$7,Оценки!$L$17) | M7: =AVERAGE(Оценки!$M$7,Оценки!$M$17) | N7: =MAX(Оценки!$N$7,Оценки!$N$17) | O7: =MIN(Оценки!$O$7,Оценки!$O$17) | P7: =AVERAGE(Оценки!$P$7,Оценки!$P$17) | Q7: =MAX(Оценки!$Q$7,Оценки!$Q$17)
A8: A3 | B8: =Концепции!$B$6 | C8: =MIN(Оценки!$C$8,Оценки!$C$18) | D8: =AVERAGE(Оценки!$D$8,Оценки!$D$18) | E8: =MAX(Оценки!$E$8,Оценки!$E$18) | F8: =MIN(Оценки!$F$8,Оценки!$F$18) | G8: =AVERAGE(Оценки!$G$8,Оценки!$G$18) | H8: =MAX(Оценки!$H$8,Оценки!$H$18) | I8: =MIN(Оценки!$I$8,Оценки!$I$18) | J8: =AVERAGE(Оценки!$J$8,Оценки!$J$18) | K8: =MAX(Оценки!$K$8,Оценки!$K$18) | L8: =MIN(Оценки!$L$8,Оценки!$L$18) | M8: =AVERAGE(Оценки!$M$8,Оценки!$M$18) | N8: =MAX(Оценки!$N$8,Оценки!$N$18) | O8: =MIN(Оценки!$O$8,Оценки!$O$18) | P8: =AVERAGE(Оценки!$P$8,Оценки!$P$18) | Q8: =MAX(Оценки!$Q$8,Оценки!$Q$18)
A9: A4 | B9: =Концепции!$B$7 | C9: =MIN(Оценки!$C$9,Оценки!$C$19) | D9: =AVERAGE(Оценки!$D$9,Оценки!$D$19) | E9: =MAX(Оценки!$E$9,Оценки!$E$19) | F9: =MIN(Оценки!$F$9,Оценки!$F$19) | G9: =AVERAGE(Оценки!$G$9,Оценки!$G$19) | H9: =MAX(Оценки!$H$9,Оценки!$H$19) | I9: =MIN(Оценки!$I$9,Оценки!$I$19) | J9: =AVERAGE(Оценки!$J$9,Оценки!$J$19) | K9: =MAX(Оценки!$K$9,Оценки!$K$19) | L9: =MIN(Оценки!$L$9,Оценки!$L$19) | M9: =AVERAGE(Оценки!$M$9,Оценки!$M$19) | N9: =MAX(Оценки!$N$9,Оценки!$N$19) | O9: =MIN(Оценки!$O$9,Оценки!$O$19) | P9: =AVERAGE(Оценки!$P$9,Оценки!$P$19) | Q9: =MAX(Оценки!$Q$9,Оценки!$Q$19)
A10: w | B10: Агрегированный вес | C10: =MIN(Оценки!$C$10,Оценки!$C$20) | D10: =AVERAGE(Оценки!$D$10,Оценки!$D$20) | E10: =MAX(Оценки!$E$10,Оценки!$E$20) | F10: =MIN(Оценки!$F$10,Оценки!$F$20) | G10: =AVERAGE(Оценки!$G$10,Оценки!$G$20) | H10: =MAX(Оценки!$H$10,Оценки!$H$20) | I10: =MIN(Оценки!$I$10,Оценки!$I$20) | J10: =AVERAGE(Оценки!$J$10,Оценки!$J$20) | K10: =MAX(Оценки!$K$10,Оценки!$K$20) | L10: =MIN(Оценки!$L$10,Оценки!$L$20) | M10: =AVERAGE(Оценки!$M$10,Оценки!$M$20) | N10: =MAX(Оценки!$N$10,Оценки!$N$20) | O10: =MIN(Оценки!$O$10,Оценки!$O$20) | P10: =AVERAGE(Оценки!$P$10,Оценки!$P$20) | Q10: =MAX(Оценки!$Q$10,Оценки!$Q$20)
B11: Тип критерия | C11: =Концепции!$C$11 | F11: =Концепции!$C$12 | I11: =Концепции!$C$13 | L11: =Концепции!$C$14 | O11: =Концепции!$C$15
B12: u* = max u | C12: =MAX(E6:E9) | F12: =MAX(H6:H9) | I12: =MAX(K6:K9) | L12: =MAX(N6:N9) | O12: =MAX(Q6:Q9)
B13: l⁻ = min l | C13: =MIN(C6:C9) | F13: =MIN(F6:F9) | I13: =MIN(I6:I9) | L13: =MIN(L6:L9) | O13: =MIN(O6:O9)
A15: 2. Нормализованная матрица
B16: Концепция | C16: =Концепции!$B$11 | F16: =Концепции!$B$12 | I16: =Концепции!$B$13 | L16: =Концепции!$B$14 | O16: =Концепции!$B$15
C17: l | D17: m | E17: u | F17: l | G17: m | H17: u | I17: l | J17: m | K17: u | L17: l | M17: m | N17: u | O17: l | P17: m | Q17: u
A18: A1 | B18: =Концепции!$B$4 | C18: =IF($C$11="max",C6/$C$12,$C$13/E6) | D18: =IF($C$11="max",D6/$C$12,$C$13/D6) | E18: =IF($C$11="max",E6/$C$12,$C$13/C6) | F18: =IF($F$11="max",F6/$F$12,$F$13/H6) | G18: =IF($F$11="max",G6/$F$12,$F$13/G6) | H18: =IF($F$11="max",H6/$F$12,$F$13/F6) | I18: =IF($I$11="max",I6/$I$12,$I$13/K6) | J18: =IF($I$11="max",J6/$I$12,$I$13/J6) | K18: =IF($I$11="max",K6/$I$12,$I$13/I6) | L18: =IF($L$11="max",L6/$L$12,$L$13/N6) | M18: =IF($L$11="max",M6/$L$12,$L$13/M6) | N18: =IF($L$11="max",N6/$L$12,$L$13/L6) | O18: =IF($O$11="max",O6/$O$12,$O$13/Q6) | P18: =IF($O$11="max",P6/$O$12,$O$13/P6) | Q18: =IF($O$11="max",Q6/$O$12,$O$13/O6)
A19: A2 | B19: =Концепции!$B$5 | C19: =IF($C$11="max",C7/$C$12,$C$13/E7) | D19: =IF($C$11="max",D7/$C$12,$C$13/D7) | E19: =IF($C$11="max",E7/$C$12,$C$13/C7) | F19: =IF($F$11="max",F7/$F$12,$F$13/H7) | G19: =IF($F$11="max",G7/$F$12,$F$13/G7) | H19: =IF($F$11="max",H7/$F$12,$F$13/F7) | I19: =IF($I$11="max",I7/$I$12,$I$13/K7) | J19: =IF($I$11="max",J7/$I$12,$I$13/J7) | K19: =IF($I$11="max",K7/$I$12,$I$13/I7) | L19: =IF($L$11="max",L7/$L$12,$L$13/N7) | M19: =IF($L$11="max",M7/$L$12,$L$13/M7) | N19: =IF($L$11="max",N7/$L$12,$L$13/L7) | O19: =IF($O$11="max",O7/$O$12,$O$13/Q7) | P19: =IF($O$11="max",P7/$O$12,$O$13/P7) | Q19: =IF($O$11="max",Q7/$O$12,$O$13/O7)
A20: A3 | B20: =Концепции!$B$6 | C20: =IF($C$11="max",C8/$C$12,$C$13/E8) | D20: =IF($C$11="max",D8/$C$12,$C$13/D8) | E20: =IF($C$11="max",E8/$C$12,$C$13/C8) | F20: =IF($F$11="max",F8/$F$12,$F$13/H8) | G20: =IF($F$11="max",G8/$F$12,$F$13/G8) | H20: =IF($F$11="max",H8/$F$12,$F$13/F8) | I20: =IF($I$11="max",I8/$I$12,$I$13/K8) | J20: =IF($I$11="max",J8/$I$12,$I$13/J8) | K20: =IF($I$11="max",K8/$I$12,$I$13/I8) | L20: =IF($L$11="max",L8/$L$12,$L$13/N8) | M20: =IF($L$11="max",M8/$L$12,$L$13/M8) | N20: =IF($L$11="max",N8/$L$12,$L$13/L8) | O20: =IF($O$11="max",O8/$O$12,$O$13/Q8) | P20: =IF($O$11="max",P8/$O$12,$O$13/P8) | Q20: =IF($O$11="max",Q8/$O$12,$O$13/O8)
A21: A4 | B21: =Концепции!$B$7 | C21: =IF($C$11="max",C9/$C$12,$C$13/E9) | D21: =IF($C$11="max",D9/$C$12,$C$13/D9) | E21: =IF($C$11="max",E9/$C$12,$C$13/C9) | F21: =IF($F$11="max",F9/$F$12,$F$13/H9) | G21: =IF($F$11="max",G9/$F$12,$F$13/G9) | H21: =IF($F$11="max",H9/$F$12,$F$13/F9) | I21: =IF($I$11="max",I9/$I$12,$I$13/K9) | J21: =IF($I$11="max",J9/$I$12,$I$13/J9) | K21: =IF($I$11="max",K9/$I$12,$I$13/I9) | L21: =IF($L$11="max",L9/$L$12,$L$13/N9) | M21: =IF($L$11="max",M9/$L$12,$L$13/M9) | N21: =IF($L$11="max",N9/$L$12,$L$13/L9) | O21: =IF($O$11="max",O9/$O$12,$O$13/Q9) | P21: =IF($O$11="max",P9/$O$12,$O$13/P9) | Q21: =IF($O$11="max",Q9/$O$12,$O$13/O9)
A23: 3. Взвешенная нормализованная матрица v = r ⊗ w
B24: Концепция | C24: =Концепции!$B$11 | F24: =Концепции!$B$12 | I24: =Концепции!$B$13 | L24: =Концепции!$B$14 | O24: =Концепции!$B$15
C25: l | D25: m | E25: u | F25: l | G25: m | H25: u | I25: l | J25: m | K25: u | L25: l | M25: m | N25: u | O25: l | P25: m | Q25: u
A26: A1 | B26: =Концепции!$B$4 | C26: =C18*$C$10 | D26: =D18*$D$10 | E26: =E18*$E$10 | F26: =F18*$F$10 | G26: =G18*$G$10 | H26: =H18*$H$10 | I26: =I18*$I$10 | J26: =J18*$J$10 | K26: =K18*$K$10 | L26: =L18*$L$10 | M26: =M18*$M$10 | N26: =N18*$N$10 | O26: =O18*$O$10 | P26: =P18*$P$10 | Q26: =Q18*$Q$10
A27: A2 | B27: =Концепции!$B$5 | C27: =C19*$C$10 | D27: =D19*$D$10 | E27: =E19*$E$10 | F27: =F19*$F$10 | G27: =G19*$G$10 | H27: =H19*$H$10 | I27: =I19*$I$10 | J27: =J19*$J$10 | K27: =K19*$K$10 | L27: =L19*$L$10 | M27: =M19*$M$10 | N27: =N19*$N$10 | O27: =O19*$O$10 | P27: =P19*$P$10 | Q27: =Q19*$Q$10
A28: A3 | B28: =Концепции!$B$6 | C28: =C20*$C$10 | D28: =D20*$D$10 | E28: =E20*$E$10 | F28: =F20*$F$10 | G28: =G20*$G$10 | H28: =H20*$H$10 | I28: =I20*$I$10 | J28: =J20*$J$10 | K28: =K20*$K$10 | L28: =L20*$L$10 | M28: =M20*$M$10 | N28: =N20*$N$10 | O28: =O20*$O$10 | P28: =P20*$P$10 | Q28: =Q20*$Q$10
A29: A4 | B29: =Концепции!$B$7 | C29: =C21*$C$10 | D29: =D21*$D$10 | E29: =E21*$E$10 | F29: =F21*$F$10 | G29: =G21*$G$10 | H29: =H21*$H$10 | I29: =I21*$I$10 | J29: =J21*$J$10 | K29: =K21*$K$10 | L29: =L21*$L$10 | M29: =M21*$M$10 | N29: =N21*$N$10 | O29: =O21*$O$10 | P29: =P21*$P$10 | Q29: =Q21*$Q$10
A30: A* | B30: Идеальное решение | C30: =MAX(E26:E29) | D30: =MAX(E26:E29) | E30: =MAX(E26:E29) | F30: =MAX(H26:H29) | G30: =MAX(H26:H29) | H30: =MAX(H26:H29) | I30: =MAX(K26:K29) | J30: =MAX(K26:K29) | K30: =MAX(K26:K29) | L30: =MAX(N26:N29) | M30: =MAX(N26:N29) | N30: =MAX(N26:N29) | O30: =MAX(Q26:Q29) | P30: =MAX(Q26:Q29) | Q30: =MAX(Q26:Q29)
A31: A⁻ | B31: Антиидеальное решение | C31: =MIN(C26:C29) | D31: =MIN(C26:C29) | E31: =MIN(C26:C29) | F31: =MIN(F26:F29) | G31: =MIN(F26:F29) | H31: =MIN(F26:F29) | I31: =MIN(I26:I29) | J31: =MIN(I26:I29) | K31: =MIN(I26:I29) | L31: =MIN(L26:L29) | M31: =MIN(L26:L29) | N31: =MIN(L26:L29) | O31: =MIN(O26:O29) | P31: =MIN(O26:O29) | Q31: =MIN(O26:O29)
A33: 4. Расстояния до A* и A⁻, коэффициент близости
B34: Концепция | C34: d*(C1) | D34: d*(C2) | E34: d*(C3) | F34: d*(C4) | G34: d*(C5) | H34: D* | I34: d⁻(C1) | J34: d⁻(C2) | K34: d⁻(C3) | L34: d⁻(C4) | M34: d⁻(C5) | N34: D⁻ | O34: CC | P34: Ранг
A35: A1 | B35: =Концепции!$B$4 | C35: =SQRT(((C26-C$30)^2+(D26-D$30)^2+(E26-E$30)^2)/3) | D35: =SQRT(((F26-F$30)^2+(G26-G$30)^2+(H26-H$30)^2)/3) | E35: =SQRT(((I26-I$30)^2+(J26-J$30)^2+(K26-K$30)^2)/3) | F35: =SQRT(((L26-L$30)^2+(M26-M$30)^2+(N26-N$30)^2)/3) | G35: =SQRT(((O26-O$30)^2+(P26-P$30)^2+(Q26-Q$30)^2)/3) | H35: =SUM(C35:G35) | I35: =SQRT(((C26-C$31)^2+(D26-D$31)^2+(E26-E$31)^2)/3) | J35: =SQRT(((F26-F$31)^2+(G26-G$31)^2+(H26-H$31)^2)/3) | K35: =SQRT(((I26-I$31)^2+(J26-J$31)^2+(K26-K$31)^2)/3) | L35: =SQRT(((L26-L$31)^2+(M26-M$31)^2+(N26-N$31)^2)/3) | M35: =SQRT(((O26-O$31)^2+(P26-P$31)^2+(Q26-Q$31)^2)/3) | N35: =SUM(I35:M35) | O35: =N35/(H35+N35) | P35: =RANK(O35,$O$35:$O$38)
A36: A2 | B36: =Концепции!$B$5 | C36: =SQRT(((C27-C$30)^2+(D27-D$30)^2+(E27-E$30)^2)/3) | D36: =SQRT(((F27-F$30)^2+(G27-G$30)^2+(H27-H$30)^2)/3) | E36: =SQRT(((I27-I$30)^2+(J27-J$30)^2+(K27-K$30)^2)/3) | F36: =SQRT(((L27-L$30)^2+(M27-M$30)^2+(N27-N$30)^2)/3) | G36: =SQRT(((O27-O$30)^2+(P27-P$30)^2+(Q27-Q$30)^2)/3) | H36: =SUM(C36:G36) | I36: =SQRT(((C27-C$31)^2+(D27-D$31)^2+(E27-E$31)^2)/3) | J36: =SQRT(((F27-F$31)^2+(G27-G$31)^2+(H27-H$31)^2)/3) | K36: =SQRT(((I27-I$31)^2+(J27-J$31)^2+(K27-K$31)^2)/3) | L36: =SQRT(((L27-L$31)^2+(M27-M$31)^2+(N27-N$31)^2)/3) | M36: =SQRT(((O27-O$31)^2+(P27-P$31)^2+(Q27-Q$31)^2)/3) | N36: =SUM(I36:M36) | O36: =N36/(H36+N36) | P36: =RANK(O36,$O$35:$O$38)
A37: A3 | B37: =Концепции!$B$6 | C37: =SQRT(((C28-C$30)^2+(D28-D$30)^2+(E28-E$30)^2)/3) | D37: =SQRT(((F28-F$30)^2+(G28-G$30)^2+(H28-H$30)^2)/3) | E37: =SQRT(((I28-I$30)^2+(J28-J$30)^2+(K28-K$30)^2)/3) | F37: =SQRT(((L28-L$30)^2+(M28-M$30)^2+(N28-N$30)^2)/3) | G37: =SQRT(((O28-O$30)^2+(P28-P$30)^2+(Q28-Q$30)^2)/3) | H37: =SUM(C37:G37) | I37: =SQRT(((C28-C$31)^2+(D28-D$31)^2+(E28-E$31)^2)/3) | J37: =SQRT(((F28-F$31)^2+(G28-G$31)^2+(H28-H$31)^2)/3) | K37: =SQRT(((I28-I$31)^2+(J28-J$31)^2+(K28-K$31)^2)/3) | L37: =SQRT(((L28-L$31)^2+(M28-M$31)^2+(N28-N$31)^2)/3) | M37: =SQRT(((O28-O$31)^2+(P28-P$31)^2+(Q28-Q$31)^2)/3) | N37: =SUM(I37:M37) | O37: =N37/(H37+N37) | P37: =RANK(O37,$O$35:$O$38)
A38: A4 | B38: =Концепции!$B$7 | C38: =SQRT(((C29-C$30)^2+(D29-D$30)^2+(E29-E$30)^2)/3) | D38: =SQRT(((F29-F$30)^2+(G29-G$30)^2+(H29-H$30)^2)/3) | E38: =SQRT(((I29-I$30)^2+(J29-J$30)^2+(K29-K$30)^2)/3) | F38: =SQRT(((L29-L$30)^2+(M29-M$30)^2+(N29-N$30)^2)/3) | G38: =SQRT(((O29-O$30)^2+(P29-P$30)^2+(Q29-Q$30)^2)/3) | H38: =SUM(C38:G38) | I38: =SQRT(((C29-C$31)^2+(D29-D$31)^2+(E29-E$31)^2)/3) | J38: =SQRT(((F29-F$31)^2+(G29-G$31)^2+(H29-H$31)^2)/3) | K38: =SQRT(((I29-I$31)^2+(J29-J$31)^2+(K29-K$31)^2)/3) | L38: =SQRT(((L29-L$31)^2+(M29-M$31)^2+(N29-N$31)^2)/3) | M38: =SQRT(((O29-O$31)^2+(P29-P$31)^2+(Q29-Q$31)^2)/3) | N38: =SUM(I38:M38) | O38: =N38/(H38+N38) | P38: =RANK(O38,$O$35:$O$38)

Sheet МАИ Эксперт 1
A1: МАИ: суждения эксперта 1 (Савелий Хвостов)
A2: Заполняется только верхний треугольник (жёлтые ячейки): насколько строка лучше/важнее столбца по шкале Саати. Дроби вводить как =1/3.
A4: Критерии: парные сравнения важности
C5: =Концепции!$B$11 | D5: =Концепции!$B$12 | E5: =Концепции!$B$13 | F5: =Концепции!$B$14 | G5: =Концепции!$B$15 | H5: Ср. геом. | I5: Вес
A6: C1 | B6: =Концепции!$B$11 | C6: 1 | D6: 5 | E6: 2 | F6: 7 | G6: 3 | H6: =PRODUCT(C6:G6)^(1/5) | I6: =H6/SUM($H$6:$H$10)
A7: C2 | B7: =Концепции!$B$12 | C7: =1/D6 | D7: 1 | E7: =1/6 | F7: =1/3 | G7: =1/3 | H7: =PRODUCT(C7:G7)^(1/5) | I7: =H7/SUM($H$6:$H$10)
A8: C3 | B8: =Концепции!$B$13 | C8: =1/E6 | D8: =1/E7 | E8: 1 | F8: 2 | G8: 2 | H8: =PRODUCT(C8:G8)^(1/5) | I8: =H8/SUM($H$6:$H$10)
A9: C4 | B9: =Концепции!$B$14 | C9: =1/F6 | D9: =1/F7 | E9: =1/F8 | F9: 1 | G9: =1/4 | H9: =PRODUCT(C9:G9)^(1/5) | I9: =H9/SUM($H$6:$H$10)
A10: C5 | B10: =Концепции!$B$15 | C10: =1/G6 | D10: =1/G7 | E10: =1/G8 | F10: =1/G9 | G10: 1 | H10: =PRODUCT(C10:G10)^(1/5) | I10: =H10/SUM($H$6:$H$10)
B11: Сумма столбца | C11: =SUM(C6:C10) | D11: =SUM(D6:D10) | E11: =SUM(E6:E10) | F11: =SUM(F6:F10) | G11: =SUM(G6:G10)
B12: λmax | C12: =C11*I6+D11*I7+E11*I8+F11*I9+G11*I10
B13: ИС = (λmax−n)/(n−1) | C13: =(C12-5)/(5-1)
B14: ОС = ИС / СИ (СИ = 1,12) | C14: =C13/1.12 | D14: =IF(C14<=0.1,"согласовано","пересмотреть")
A18: Концепции по критерию C1 | E18: =Концепции!$B$11
C19: =Концепции!$B$4 | D19: =Концепции!$B$5 | E19: =Концепции!$B$6 | F19: =Концепции!$B$7 | G19: Ср. геом. | H19: Вес
A20: A1 | B20: =Концепции!$B$4 | C20: 1 | D20: 3 | E20: 5 | F20: 2 | G20: =PRODUCT(C20:F20)^(1/4) | H20: =G20/SUM($G$20:$G$23)
A21: A2 | B21: =Концепции!$B$5 | C21: =1/D20 | D21: 1 | E21: 2 | F21: 2 | G21: =PRODUCT(C21:F21)^(1/4) | H21: =G21/SUM($G$20:$G$23)
A22: A3 | B22: =Концепции!$B$6 | C22: =1/E20 | D22: =1/E21 | E22: 1 | F22: =1/5 | G22: =PRODUCT(C22:F22)^(1/4) | H22: =G22/SUM($G$20:$G$23)
A23: A4 | B23: =Концепции!$B$7 | C23: =1/F20 | D23: =1/F21 | E23: =1/F22 | F23: 1 | G23: =PRODUCT(C23:F23)^(1/4) | H23: =G23/SUM($G$20:$G$23)
B24: Сумма столбца | C24: =SUM(C20:C23) | D24: =SUM(D20:D23) | E24: =SUM(E20:E23) | F24: =SUM(F20:F23)
B25: λmax | C25: =C24*H20+D24*H21+E24*H22+F24*H23
B26: ИС = (λmax−n)/(n−1) | C26: =(C25-4)/(4-1)
B27: ОС = ИС / СИ (СИ = 0,90) | C27: =C26/0.9 | D27: =IF(C27<=0.1,"согласовано","пересмотреть")
A32: Концепции по критерию C2 | E32: =Концепции!$B$12
C33: =Концепции!$B$4 | D33: =Концепции!$B$5 | E33: =Концепции!$B$6 | F33: =Концепции!$B$7 | G33: Ср. геом. | H33: Вес
A34: A1 | B34: =Концепции!$B$4 | C34: 1 | D34: 5 | E34: 1 | F34: =1/4 | G34: =PRODUCT(C34:F34)^(1/4) | H34: =G34/SUM($G$34:$G$37)
A35: A2 | B35: =Концепции!$B$5 | C35: =1/D34 | D35: 1 | E35: =1/4 | F35: =1/5 | G35: =PRODUCT(C35:F35)^(1/4) | H35: =G35/SUM($G$34:$G$37)
A36: A3 | B36: =Концепции!$B$6 | C36: =1/E34 | D36: =1/E35 | E36: 1 | F36: =1/5 | G36: =PRODUCT(C36:F36)^(1/4) | H36: =G36/SUM($G$34:$G$37)
A37: A4 | B37: =Концепции!$B$7 | C37: =1/F34 | D37: =1/F35 | E37: =1/F36 | F37: 1 | G37: =PRODUCT(C37:F37)^(1/4) | H37: =G37/SUM($G$34:$G$37)
B38: Сумма столбца | C38: =SUM(C34:C37) | D38: =SUM(D34:D37) | E38: =SUM(E34:E37) | F38: =SUM(F34:F37)
B39: λmax | C39: =C38*H34+D38*H35+E38*H36+F38*H37
B40: ИС = (λmax−n)/(n−1) | C40: =(C39-4)/(4-1)
B41: ОС = ИС / СИ (СИ = 0,90) | C41: =C40/0.9 | D41: =IF(C41<=0.1,"согласовано","пересмотреть")
A46: Концепции по критерию C3 | E46: =Концепции!$B$13
C47: =Концепции!$B$4 | D47: =Концепции!$B$5 | E47: =Концепции!$B$6 | F47: =Концепции!$B$7 | G47: Ср. геом. | H47: Вес
A48: A1 | B48: =Концепции!$B$4 | C48: 1 | D48: 5 | E48: =1/4 | F48: =1/6 | G48: =PRODUCT(C48:F48)^(1/4) | H48: =G48/SUM($G$48:$G$51)
A49: A2 | B49: =Концепции!$B$5 | C49: =1/D48 | D49: 1 | E49: =1/7 | F49: =1/6 | G49: =PRODUCT(C49:F49)^(1/4) | H49: =G49/SUM($G$48:$G$51)
A50: A3 | B50: =Концепции!$B$6 | C50: =1/E48 | D50: =1/E49 | E50: 1 | F50: =1/2 | G50: =PRODUCT(C50:F50)^(1/4) | H50: =G50/SUM($G$48:$G$51)
A51: A4 | B51: =Концепции!$B$7 | C51: =1/F48 | D51: =1/F49 | E51: =1/F50 | F51: 1 | G51: =PRODUCT(C51:F51)^(1/4) | H51: =G51/SUM($G$48:$G$51)
B52: Сумма столбца | C52: =SUM(C48:C51) | D52: =SUM(D48:D51) | E52: =SUM(E48:E51) | F52: =SUM(F48:F51)
...

Sheet МАИ Эксперт 2
A1: МАИ: суждения эксперта 2 (Екатерина Козлова)
A2: Заполняется только верхний треугольник (жёлтые ячейки): насколько строка лучше/важнее столбца по шкале Саати. Дроби вводить как =1/3.
A4: Критерии: парные сравнения важности
C5: =Концепции!$B$11 | D5: =Концепции!$B$12 | E5: =Концепции!$B$13 | F5: =Концепции!$B$14 | G5: =Концепции!$B$15 | H5: Ср. геом. | I5: Вес
A6: C1 | B6: =Концепции!$B$11 | C6: 1 | D6: 7 | E6: 5 | F6: 7 | G6: 3 | H6: =PRODUCT(C6:G6)^(1/5) | I6: =H6/SUM($H$6:$H$10)
A7: C2 | B7: =Концепции!$B$12 | C7: =1/D6 | D7: 1 | E7: =1/4 | F7: 3 | G7: =1/6 | H7: =PRODUCT(C7:G7)^(1/5) | I7: =H7/SUM($H$6:$H$10)
A8: C3 | B8: =Концепции!$B$13 | C8: =1/E6 | D8: =1/E7 | E8: 1 | F8: 3 | G8: =1/4 | H8: =PRODUCT(C8:G8)^(1/5) | I8: =H8/SUM($H$6:$H$10)
A9: C4 | B9: =Концепции!$B$14 | C9: =1/F6 | D9: =1/F7 | E9: =1/F8 | F9: 1 | G9: =1/6 | H9: =PRODUCT(C9:G9)^(1/5) | I9: =H9/SUM($H$6:$H$10)
A10: C5 | B10: =Концепции!$B$15 | C10: =1/G6 | D10: =1/G7 | E10: =1/G8 | F10: =1/G9 | G10: 1 | H10: =PRODUCT(C10:G10)^(1/5) | I10: =H10/SUM($H$6:$H$10)
B11: Сумма столбца | C11: =SUM(C6:C10) | D11: =SUM(D6:D10) | E11: =SUM(E6:E10) | F11: =SUM(F6:F10) | G11: =SUM(G6:G10)
B12: λmax | C12: =C11*I6+D11*I7+E11*I8+F11*I9+G11*I10
B13: ИС = (λmax−n)/(n−1) | C13: =(C12-5)/(5-1)
B14: ОС = ИС / СИ (СИ = 1,12) | C14: =C13/1.12 | D14: =IF(C14<=0.1,"согласовано","пересмотреть")
A18: Концепции по критерию C1 | E18: =Концепции!$B$11
C19: =Концепции!$B$4 | D19: =Концепции!$B$5 | E19: =Концепции!$B$6 | F19: =Концепции!$B$7 | G19: Ср. геом. | H19: Вес
A20: A1 | B20: =Концепции!$B$4 | C20: 1 | D20: 1 | E20: 3 | F20: =1/8 | G20: =PRODUCT(C20:F20)^(1/4) | H20: =G20/SUM($G$20:$G$23)
A21: A2 | B21: =Концепции!$B$5 | C21: =1/D20 | D21: 1 | E21: 2 | F21: =1/6 | G21: =PRODUCT(C21:F21)^(1/4) | H21: =G21/SUM($G$20:$G$23)
A22: A3 | B22: =Концепции!$B$6 | C22: =1/E20 | D22: =1/E21 | E22: 1 | F22: =1/8 | G22: =PRODUCT(C22:F22)^(1/4) | H22: =G22/SUM($G$20:$G$23)
A23: A4 | B23: =Концепции!$B$7 | C23: =1/F20 | D23: =1/F21 | E23: =1/F22 | F23: 1 | G23: =PRODUCT(C23:F23)^(1/4) | H23: =G23/SUM($G$20:$G$23)
B24: Сумма столбца | C24: =SUM(C20:C23) | D24: =SUM(D20:D23) | E24: =SUM(E20:E23) | F24: =SUM(F20:F23)
B25: λmax | C25: =C24*H20+D24*H21+E24*H22+F24*H23
B26: ИС = (λmax−n)/(n−1) | C26: =(C25-4)/(4-1)
B27: ОС = ИС / СИ (СИ = 0,90) | C27: =C26/0.9 | D27: =IF(C27<=0.1,"согласовано","пересмотреть")
A32: Концепции по критерию C2 | E32: =Концепции!$B$12
C33: =Концепции!$B$4 | D33: =Концепции!$B$5 | E33: =Концепции!$B$6 | F33: =Концепции!$B$7 | G33: Ср. геом. | H33: Вес
A34: A1 | B34: =Концепции!$B$4 | C34: 1 | D34: 1 | E34: 5 | F34: 3 | G34: =PRODUCT(C34:F34)^(1/4) | H34: =G34/SUM($G$34:$G$37)
A35: A2 | B35: =Концепции!$B$5 | C35: =1/D34 | D35: 1 | E35: 5 | F35: 3 | G35: =PRODUCT(C35:F35)^(1/4) | H35: =G35/SUM($G$34:$G$37)
A36: A3 | B36: =Концепции!$B$6 | C36: =1/E34 | D36: =1/E35 | E36: 1 | F36: =1/6 | G36: =PRODUCT(C36:F36)^(1/4) | H36: =G36/SUM($G$34:$G$37)
A37: A4 | B37: =Концепции!$B$7 | C37: =1/F34 | D37: =1/F35 | E37: =1/F36 | F37: 1 | G37: =PRODUCT(C37:F37)^(1/4) | H37: =G37/SUM($G$34:$G$37)
B38: Сумма столбца | C38: =SUM(C34:C37) | D38: =SUM(D34:D37) | E38: =SUM(E34:E37) | F38: =SUM(F34:F37)
B39: λmax | C39: =C38*H34+D38*H35+E38*H36+F38*H37
B40: ИС = (λmax−n)/(n−1) | C40: =(C39-4)/(4-1)
B41: ОС = ИС / СИ (СИ = 0,90) | C41: =C40/0.9 | D41: =IF(C41<=0.1,"согласовано","пересмотреть")
A46: Концепции по критерию C3 | E46: =Концепции!$B$13
C47: =Концепции!$B$4 | D47: =Концепции!$B$5 | E47: =Концепции!$B$6 | F47: =Концепции!$B$7 | G47: Ср. геом. | H47: Вес
A48: A1 | B48: =Концепции!$B$4 | C48: 1 | D48: 1 | E48: 5 | F48: 3 | G48: =PRODUCT(C48:F48)^(1/4) | H48: =G48/SUM($G$48:$G$51)
A49: A2 | B49: =Концепции!$B$5 | C49: =1/D48 | D49: 1 | E49: 5 | F49: 3 | G49: =PRODUCT(C49:F49)^(1/4) | H49: =G49/SUM($G$48:$G$51)
A50: A3 | B50: =Концепции!$B$6 | C50: =1/E48 | D50: =1/E49 | E50: 1 | F50: =1/6 | G50: =PRODUCT(C50:F50)^(1/4) | H50: =G50/SUM($G$48:$G$51)
A51: A4 | B51: =Концепции!$B$7 | C51: =1/F48 | D51: =1/F49 | E51: =1/F50 | F51: 1 | G51: =PRODUCT(C51:F51)^(1/4) | H51: =G51/SUM($G$48:$G$51)
B52: Сумма столбца | C52: =SUM(C48:C51) | D52: =SUM(D48:D51) | E52: =SUM(E48:E51) | F52: =SUM(F48:F51)
...

Sheet МАИ
A1: Коллективный МАИ: поэлементное среднее геометрическое суждений экспертов
A2: Иерархия: цель «Выбор концепции проекта» → критерии C1–C5 → концепции A1–A4.
A4: Критерии: парные сравнения важности
C5: =Концепции!$B$11 | D5: =Концепции!$B$12 | E5: =Концепции!$B$13 | F5: =Концепции!$B$14 | G5: =Концепции!$B$15 | H5: Ср. геом. | I5: Вес
A6: C1 | B6: =Концепции!$B$11 | C6: 1 | D6: =('МАИ Эксперт 1'!D6*'МАИ Эксперт 2'!D6)^(1/2) | E6: =('МАИ Эксперт 1'!E6*'МАИ Эксперт 2'!E6)^(1/2) | F6: =('МАИ Эксперт 1'!F6*'МАИ Эксперт 2'!F6)^(1/2) | G6: =('МАИ Эксперт 1'!G6*'МАИ Эксперт 2'!G6)^(1/2) | H6: =PRODUCT(C6:G6)^(1/5) | I6: =H6/SUM($H$6:$H$10)
A7: C2 | B7: =Концепции!$B$12 | C7: =1/D6 | D7: 1 | E7: =('МАИ Эксперт 1'!E7*'МАИ Эксперт 2'!E7)^(1/2) | F7: =('МАИ Эксперт 1'!F7*'МАИ Эксперт 2'!F7)^(1/2) | G7: =('МАИ Эксперт 1'!G7*'МАИ Эксперт 2'!G7)^(1/2) | H7: =PRODUCT(C7:G7)^(1/5) | I7: =H7/SUM($H$6:$H$10)
A8: C3 | B8: =Концепции!$B$13 | C8: =1/E6 | D8: =1/E7 | E8: 1 | F8: =('МАИ Эксперт 1'!F8*'МАИ Эксперт 2'!F8)^(1/2) | G8: =('МАИ Эксперт 1'!G8*'МАИ Эксперт 2'!G8)^(1/2) | H8: =PRODUCT(C8:G8)^(1/5) | I8: =H8/SUM($H$6:$H$10)
A9: C4 | B9: =Концепции!$B$14 | C9: =1/F6 | D9: =1/F7 | E9: =1/F8 | F9: 1 | G9: =('МАИ Эксперт 1'!G9*'МАИ Эксперт 2'!G9)^(1/2) | H9: =PRODUCT(C9:G9)^(1/5) | I9: =H9/SUM($H$6:$H$10)
A10: C5 | B10: =Концепции!$B$15 | C10: =1/G6 | D10: =1/G7 | E10: =1/G8 | F10: =1/G9 | G10: 1 | H10: =PRODUCT(C10:G10)^(1/5) | I10: =H10/SUM($H$6:$H$10)
B11: Сумма столбца | C11: =SUM(C6:C10) | D11: =SUM(D6:D10) | E11: =SUM(E6:E10) | F11: =SUM(F6:F10) | G11: =SUM(G6:G10)
B12: λmax | C12: =C11*I6+D11*I7+E11*I8+F11*I9+G11*I10
B13: ИС = (λmax−n)/(n−1) | C13: =(C12-5)/(5-1)
B14: ОС = ИС / СИ (СИ = 1,12) | C14: =C13/1.12 | D14: =IF(C14<=0.1,"согласовано","пересмотреть")
A18: Концепции по критерию C1 | E18: =Концепции!$B$11
C19: =Концепции!$B$4 | D19: =Концепции!$B$5 | E19: =Концепции!$B$6 | F19: =Концепции!$B$7 | G19: Ср. геом. | H19: Вес
A20: A1 | B20: =Концепции!$B$4 | C20: 1 | D20: =('МАИ Эксперт 1'!D20*'МАИ Эксперт 2'!D20)^(1/2) | E20: =('МАИ Эксперт 1'!E20*'МАИ Эксперт 2'!E20)^(1/2) | F20: =('МАИ Эксперт 1'!F20*'МАИ Эксперт 2'!F20)^(1/2) | G20: =PRODUCT(C20:F20)^(1/4) | H20: =G20/SUM($G$20:$G$23)
A21: A2 | B21: =Концепции!$B$5 | C21: =1/D20 | D21: 1 | E21: =('МАИ Эксперт 1'!E21*'МАИ Эксперт 2'!E21)^(1/2) | F21: =('МАИ Эксперт 1'!F21*'МАИ Эксперт 2'!F21)^(1/2) | G21: =PRODUCT(C21:F21)^(1/4) | H21: =G21/SUM($G$20:$G$23)
A22: A3 | B22: =Концепции!$B$6 | C22: =1/E20 | D22: =1/E21 | E22: 1 | F22: =('МАИ Эксперт 1'!F22*'МАИ Эксперт 2'!F22)^(1/2) | G22: =PRODUCT(C22:F22)^(1/4) | H22: =G22/SUM($G$20:$G$23)
A23: A4 | B23: =Концепции!$B$7 | C23: =1/F20 | D23: =1/F21 | E23: =1/F22 | F23: 1 | G23: =PRODUCT(C23:F23)^(1/4) | H23: =G23/SUM($G$20:$G$23)
B24: Сумма столбца | C24: =SUM(C20:C23) | D24: =SUM(D20:D23) | E24: =SUM(E20:E23) | F24: =SUM(F20:F23)
B25: λmax | C25: =C24*H20+D24*H21+E24*H22+F24*H23
B26: ИС = (λmax−n)/(n−1) | C26: =(C25-4)/(4-1)
B27: ОС = ИС / СИ (СИ = 0,90) | C27: =C26/0.9 | D27: =IF(C27<=0.1,"согласовано","пересмотреть")
A32: Концепции по критерию C2 | E32: =Концепции!$B$12
C33: =Концепции!$B$4 | D33: =Концепции!$B$5 | E33: =Концепции!$B$6 | F33: =Концепции!$B$7 | G33: Ср. геом. | H33: Вес
A34: A1 | B34: =Концепции!$B$4 | C34: 1 | D34: =('МАИ Эксперт 1'!D34*'МАИ Эксперт 2'!D34)^(1/2) | E34: =('МАИ Эксперт 1'!E34*'МАИ Эксперт 2'!E34)^(1/2) | F34: =('МАИ Эксперт 1'!F34*'МАИ Эксперт 2'!F34)^(1/2) | G34: =PRODUCT(C34:F34)^(1/4) | H34: =G34/SUM($G$34:$G$37)
A35: A2 | B35: =Концепции!$B$5 | C35: =1/D34 | D35: 1 | E35: =('МАИ Эксперт 1'!E35*'МАИ Эксперт 2'!E35)^(1/2) | F35: =('МАИ Эксперт 1'!F35*'МАИ Эксперт 2'!F35)^(1/2) | G35: =PRODUCT(C35:F35)^(1/4) | H35: =G35/SUM($G$34:$G$37)
A36: A3 | B36: =Концепции!$B$6 | C36: =1/E34 | D36: =1/E35 | E36: 1 | F36: =('МАИ Эксперт 1'!F36*'МАИ Эксперт 2'!F36)^(1/2) | G36: =PRODUCT(C36:F36)^(1/4) | H36: =G36/SUM($G$34:$G$37)
A37: A4 | B37: =Концепции!$B$7 | C37: =1/F34 | D37: =1/F35 | E37: =1/F36 | F37: 1 | G37: =PRODUCT(C37:F37)^(1/4) | H37: =G37/SUM($G$34:$G$37)
B38: Сумма столбца | C38: =SUM(C34:C37) | D38: =SUM(D34:D37) | E38: =SUM(E34:E37) | F38: =SUM(F34:F37)
B39: λmax | C39: =C38*H34+D38*H35+E38*H36+F38*H37
B40: ИС = (λmax−n)/(n−1) | C40: =(C39-4)/(4-1)
B41: ОС = ИС / СИ (СИ = 0,90) | C41: =C40/0.9 | D41: =IF(C41<=0.1,"согласовано","пересмотреть")
A46: Концепции по критерию C3 | E46: =Концепции!$B$13
C47: =Концепции!$B$4 | D47: =Концепции!$B$5 | E47: =Концепции!$B$6 | F47: =Концепции!$B$7 | G47: Ср. геом. | H47: Вес
A48: A1 | B48: =Концепции!$B$4 | C48: 1 | D48: =('МАИ Эксперт 1'!D48*'МАИ Эксперт 2'!D48)^(1/2) | E48: =('МАИ Эксперт 1'!E48*'МАИ Эксперт 2'!E48)^(1/2) | F48: =('МАИ Эксперт 1'!F48*'МАИ Эксперт 2'!F48)^(1/2) | G48: =PRODUCT(C48:F48)^(1/4) | H48: =G48/SUM($G$48:$G$51)
A49: A2 | B49: =Концепции!$B$5 | C49: =1/D48 | D49: 1 | E49: =('МАИ Эксперт 1'!E49*'МАИ Эксперт 2'!E49)^(1/2) | F49: =('МАИ Эксперт 1'!F49*'МАИ Эксперт 2'!F49)^(1/2) | G49: =PRODUCT(C49:F49)^(1/4) | H49: =G49/SUM($G$48:$G$51)
A50: A3 | B50: =Концепции!$B$6 | C50: =1/E48 | D50: =1/E49 | E50: 1 | F50: =('МАИ Эксперт 1'!F50*'МАИ Эксперт 2'!F50)^(1/2) | G50: =PRODUCT(C50:F50)^(1/4) | H50: =G50/SUM($G$48:$G$51)
A51: A4 | B51: =Концепции!$B$7 | C51: =1/F48 | D51: =1/F49 | E51: =1/F50 | F51: 1 | G51: =PRODUCT(C51:F51)^(1/4) | H51: =G51/SUM($G$48:$G$51)
B52: Сумма столбца | C52: =SUM(C48:C51) | D52: =SUM(D48:D51) | E52: =SUM(E48:E51) | F52: =SUM(F48:F51)
...

Sheet Итог
A1: Итог фазы 1
A3: Код | B3: Концепция | C3: TOPSIS: CC | D3: TOPSIS: ранг | E3: МАИ: приоритет | F3: МАИ: ранг | G3: Сумма рангов
A4: A1 | B4: =Концепции!$B$4 | C4: =IFERROR(TOPSIS!O35,"нет данных") | D4: =IFERROR(TOPSIS!P35,"") | E4: =IFERROR(МАИ!H90,"нет данных") | F4: =IFERROR(МАИ!I90,"") | G4: =IFERROR(D4+F4,"")
A5: A2 | B5: =Концепции!$B$5 | C5: =IFERROR(TOPSIS!O36,"нет данных") | D5: =IFERROR(TOPSIS!P36,"") | E5: =IFERROR(МАИ!H91,"нет данных") | F5: =IFERROR(МАИ!I91,"") | G5: =IFERROR(D5+F5,"")
A6: A3 | B6: =Концепции!$B$6 | C6: =IFERROR(TOPSIS!O37,"нет данных") | D6: =IFERROR(TOPSIS!P37,"") | E6: =IFERROR(МАИ!H92,"нет данных") | F6: =IFERROR(МАИ!I92,"") | G6: =IFERROR(D6+F6,"")
A7: A4 | B7: =Концепции!$B$7 | C7: =IFERROR(TOPSIS!O38,"нет данных") | D7: =IFERROR(TOPSIS!P38,"") | E7: =IFERROR(МАИ!H93,"нет данных") | F7: =IFERROR(МАИ!I93,"") | G7: =IFERROR(D7+F7,"")
B10: Лучшая по TOPSIS | C10: =IFERROR(INDEX($B$4:$B$7,MATCH(MAX($C$4:$C$7),$C$4:$C$7,0)),"нет данных")
B11: Лучшая по МАИ | C11: =IFERROR(INDEX($B$4:$B$7,MATCH(MAX($E$4:$E$7),$E$4:$E$7,0)),"нет данных")
B12: Методы согласны? | C12: =IF(C10=C11,"да, выбрана "&C10,"нет, нужно обсуждение")
B14: Согласованность коллективных матриц МАИ (ОС)
B15: Критерии: парные сравнения важности | C15: =IFERROR(МАИ!C14,"нет данных")
B16: Концепции по критерию C1 | C16: =IFERROR(МАИ!C27,"нет данных")
B17: Концепции по критерию C2 | C17: =IFERROR(МАИ!C41,"нет данных")
B18: Концепции по критерию C3 | C18: =IFERROR(МАИ!C55,"нет данных")
B19: Концепции по критерию C4 | C19: =IFERROR(МАИ!C69,"нет данных")
B20: Концепции по критерию C5 | C20: =IFERROR(МАИ!C83,"нет данных")
